Workbook
Name data: #REF!
Name rapel: #REF!
Name Slicer_APPLICATION_YEAR: #N/A
Name Slicer_Kategori_Sumber_Dana: #N/A
Name Slicer_Kategori_Sumber_Dana1: #N/A
Name Slicer_Prodi1: #N/A
Name Slicer_Prodi21: #N/A
Name Slicer_Prodi51: #N/A
Name Slicer_Prodi81: #N/A
Name Slicer_Tahun_Usulan: #N/A
Name Slicer_Tahun_Usulan1: #N/A

Sheet Dashboard_Pengmas_08082024
A1: Kategori Sumber Dana | B1: (All)
A2: Tahun Usulan | B2: 2023
A4: Tahun/Nama Skema | B4: Total
A5: Pengmas penugasan | B5: 1
A6: pkm reguler | B6: 1
A7: Grand Total | B7: 2

Sheet Dashboard_penelitian_08082024
A2: Sumber Dana | B2: (All)
A3: Kategori Sumber Dana | B3: Internal
A5: Tahun / Skema Penelitian | B5: Sum of Tahun Usulan
A6: Penelitian Dasar | B6: 2021
A7: Rizqa Amelia Zunaidi | B7: 2021
A8: Penelitian Dana Internal (PDI) | B8: 62603
A9: Abduh Sayid Albana | B9: 2019
A10: Bernadus Anggo Seno Aji | B10: 2019
A11: Billy Montolalu | B11: 2019
A12: Dewi Rahmawati | B12: 4039
A13: Dimas Adiputra | B13: 4039
A14: Dominggo Bayu Baskara | B14: 2020
A15: Dwi Edi Setyawan | B15: 2019
A16: Farah Zakiyah Rahmanti | B16: 4039
A17: Hamzah Ulinuha Mustakim | B17: 2019
... A259: Grand Total | B259: 513678

Sheet Data Sitasi Scopus
A1: Citation Per Researchers Scopus Per September 2024 | J1: Citation Per Researchers Scopus Tahun 2024
A3: No | B3: NAMA | C3: NAMA DEPAN | D3: NAMA TENGAH | E3: NAMA BELAKANG | F3: PRODI | G3: FAKULTAS | H3: Sitasi | J3: No. | K3: Nama Lengkap | L3: Program Studi | M3: Sitasi Scopus | N3: Afiliasi
A4: 1 | B4: Dwi Edi Setyawan | C4: Dwi | D4: Edi | E4: Setyawan | F4: Teknik Komputer | G4: Fakultas Teknik Elektro | H4: 9 | J4: 1 | K4: Tri Agus Djoko Kuntjoro | L4: Teknik Telekomunikasi | M4: 0
A5: 2 | B5: Moch. Iskandar Riansyah | C5: Moch. | D5: Iskandar | E5: Riansyah | F5: Teknik Elektro | G5: Fakultas Teknik Elektro | H5: 10 | J5: 2 | K5: Dwi Edi Setyawan | L5: Teknik Komputer | M5: 10
A6: 3 | B6: Khodijah Amiroh | C6: Khodijah | D6: Amiroh | F6: Teknologi Informasi | G6: Fakultas Informatika | H6: 4 | J6: 3 | K6: Moch. Iskandar Riansyah | L6: Teknik Elektro | M6: 11
A7: 4 | B7: Dimas Adiputra | C7: Dimas | D7: Adiputra | F7: Teknik Elektro | G7: Fakultas Teknik Elektro | H7: 197 | J7: 4 | K7: Khodijah Amiroh | L7: Teknologi Informasi | M7: 7
A8: 5 | B8: Isa Hafidz | C8: Isa | D8: Hafidz | F8: Teknik Elektro | G8: Fakultas Teknik Elektro | H8: 51 | J8: 5 | K8: Dimas Adiputra | L8: Teknik Elektro | M8: 209
A9: 6 | B9: Walid Maulana Hadiansyah | C9: Walid | D9: Maulana | E9: Hadiansyah | F9: Teknik Telekomunikasi | G9: Fakultas Teknik Elektro | H9: 17 | J9: 6 | K9: Isa Hafidz | L9: Teknik Elektro | M9: 58
A10: 7 | B10: Farah Zakiyah Rahmanti | C10: Farah | D10: Zakiyah | E10: Rahmanti | F10: Teknologi Informasi | G10: Fakultas Informatika | H10: 72 | J10: 7 | K10: Walid Maulana Hadiansyah | L10: Teknik Telekomunikasi | M10: 17 | N10: Institut Teknologi Sepuluh Nopember
A11: 8 | B11: Helmy Widyantara | C11: Helmy | D11: Widyantara | F11: Teknologi Informasi | G11: Fakultas Informatika | H11: 38 | J11: 8 | K11: Farah Zakiyah Rahmanti | L11: Teknologi Informasi | M11: 75
A12: 9 | B12: Wahyu Andy Prastyabudi | C12: Wahyu | D12: Andy | E12: Prastyabudi | F12: Teknik Industri | G12: Fakultas Rekayasa Industri | H12: 10 | J12: 9 | K12: Helmy Widyantara | L12: Teknologi Informasi | M12: 39
A13: 10 | B13: Fidi Wincoko Putro | C13: Fidi | D13: Wincoko | E13: Putro | F13: RPL | G13: Fakultas Informatika | H13: 0 | J13: 10 | K13: Wahyu Andy Prastyabudi | L13: Teknik Industri | M13: 13
A14: 11 | B14: Philip Tobianto Daely | C14: Philip | D14: Tobianto | E14: Daely | F14: Teknologi Informasi | G14: Fakultas Informatika | H14: 287 | J14: 11 | K14: Fidi Wincoko Putro | L14: Rekayasa Perangkat Lunak | N14: Tidak ada
A15: 12 | B15: Anifatul Faricha | C15: Anifatul | D15: Faricha | F15: Teknik Elektro | G15: Fakultas Teknik Elektro | H15: 86 | J15: 12 | K15: Philip Tobianto Daely | L15: Teknologi Informasi | M15: 287
A16: 13 | B16: Mohammad Sholik | C16: Mohammad | D16: Sholik | F16: RPL | G16: Fakultas Informatika | H16: 2 | J16: 13 | K16: Anifatul Faricha | L16: Teknik Elektro | M16: 91
A17: 14 | B17: Anfazul Faridatul Azizah | C17: Anfazul | D17: Faridatul | E17: Azizah | F17: Sistem Informasi | G17: Fakultas Rekayasa Industri | H17: 0 | J17: 14 | K17: Mohammad Sholik | L17: Rekayasa Perangkat Lunak | M17: 3
A18: 15 | B18: Hamzah Ulinuha Mustakim | C18: Hamzah | D18: Ulinuha | E18: Mustakim | F18: Teknik Telekomunikasi | G18: Fakultas Teknik Elektro | H18: 1 | J18: 15 | K18: Anfazul Faridatul Azizah | L18: Sistem Informasi | M18: 1 | N18: Institut Teknologi Sepuluh Nopember
A19: 16 | B19: Mohamad Yani | C19: Mohamad | D19: Yani | F19: Teknik Komputer | G19: Fakultas Teknik Elektro | H19: 14 | J19: 16 | K19: Hamzah Ulinuha Mustakim | L19: Teknik Telekomunikasi | M19: 1
A20: 17 | B20: Muhsin | C20: Muhsin | F20: Teknik Telekomunikasi | G20: Fakultas Teknik Elektro | H20: 35 | J20: 17 | K20: Mohamad Yani | L20: Teknik Komputer | M20: 14
A21: 18 | B21: Nilla Rachmaningrum | C21: Nilla | D21: Rachmaningrum | F21: Teknik Telekomunikasi | G21: Fakultas Teknik Elektro | H21: 1 | J21: 18 | K21: Muhsin | L21: Teknik Telekomunikasi | M21: 36
A22: 19 | B22: Noerma Pudji Istyanto | C22: Noerma | D22: Pudji | E22: Istyanto | F22: Sistem Informasi | G22: Fakultas Rekayasa Industri | H22: 0 | J22: 19 | K22: Nilla Rachmaningrum | L22: Teknik Telekomunikasi | M22: 1
A23: 20 | B23: Lora Khaula Amifia | C23: Lora | D23: Khaula | E23: Amifia | F23: Teknik Elektro | G23: Fakultas Teknik Elektro | H23: 16 | J23: 20 | K23: Noerma Pudji Istyanto | L23: Sistem Informasi | M23: 0
A24: 21 | B24: Ully Asfari | C24: Ully | D24: Asfari | F24: Sistem Informasi | G24: Fakultas Rekayasa Industri | H24: 57 | J24: 21 | K24: Lora Khaula Amifia | L24: Teknik Elektro | M24: 16
A25: 22 | B25: Ubaidillah Umar | C25: Ubaidillah | D25: Umar | F25: Teknik Komputer | G25: Fakultas Teknik Elektro | H25: 14 | J25: 22 | K25: Ully Asfari | L25: Sistem Informasi | M25: 73
A26: 23 | B26: Oktavia Ayu Permata | C26: Oktavia | D26: Ayu | E26: Permata | F26: Teknologi Informasi | G26: Fakultas Informatika | H26: 1 | J26: 23 | K26: Ubaidillah Umar | L26: Teknik Komputer | M26: 16
A27: 24 | B27: Dominggo Bayu Baskara | C27: Dominggo | D27: Bayu | E27: Baskara | F27: Digital Bisnis | G27: Fakultas Ekonomi dan Bisnis | H27: 2 | J27: 24 | K27: Oktavia Ayu Permata | L27: Teknologi Informasi | M27: 2
A28: 25 | B28: Billy Montolalu | C28: Billy | D28: Montolalu | F28: RPL | G28: Fakultas Informatika | H28: 11 | J28: 25 | K28: Dominggo Bayu Baskara | L28: Digital Bisnis | N28: Tidak ada
A29: 26 | B29: Yupit Sudianto | C29: Yupit | D29: Sudianto | F29: Sistem Informasi | G29: Fakultas Rekayasa Industri | H29: 0 | J29: 26 | K29: Billy Montolalu | L29: Rekayasa Perangkat Lunak | M29: 11
A30: 27 | B30: Dewi Rahmawati | C30: Dewi | D30: Rahmawati | F30: RPL | G30: Fakultas Informatika | H30: 120 | J30: 27 | K30: Yupit Sudianto | L30: Sistem Informasi | M30: 0
A31: 28 | B31: Ardiansyah Al Farouq | C31: Ardiansyah | D31: Al | E31: Farouq | F31: Teknik Komputer | G31: Fakultas Teknik Elektro | H31: 17 | J31: 28 | K31: Dewi Rahmawati | L31: Rekayasa Perangkat Lunak | M31: 139
A32: 29 | B32: Ardian Yusuf Wicaksono | C32: Ardian | D32: Yusuf | E32: Wicaksono | F32: Informatika | G32: Fakultas Informatika | H32: 35 | J32: 29 | K32: Ardiansyah Al Farouq | L32: Teknik Komputer | M32: 17
A33: 30 | B33: Rahaditya Dimas Prihadianto | C33: Rahaditya | D33: Dimas | E33: Prihadianto | F33: Teknik Industri | G33: Fakultas Rekayasa Industri | H33: 3 | J33: 30 | K33: Ardian Yusuf Wicaksono | L33: Informatika | M33: 35
A34: 31 | B34: Rizqa Amelia Zunaidi | C34: Rizqa | D34: Amelia | E34: Zunaidi | F34: Teknik Industri | G34: Fakultas Rekayasa Industri | H34: 4 | J34: 31 | K34: Rahaditya Dimas Prihadianto | L34: Teknik Industri | M34: 3 | N34: Institut Teknologi Sepuluh Nopember
A35: 32 | B35: Titus Kristanto | C35: Titus | D35: Kristanto | F35: Digital Bisnis | G35: Fakultas Ekonomi dan Bisnis | H35: 27 | J35: 32 | K35: Rizqa Amelia Zunaidi | L35: Teknik Industri | M35: 7
A36: 33 | B36: Pangestu Widodo | C36: Pangestu | D36: Widodo | F36: Teknik Komputer | G36: Fakultas Teknik Elektro | H36: 0 | J36: 33 | K36: Titus Kristanto | L36: Digital Bisnis | M36: 28
A37: 34 | B37: Abduh Sayid Albana | C37: Abduh | D37: Sayid | E37: Albana | F37: Teknik Logistik | G37: Fakultas Rekayasa Industri | H37: 68 | J37: 34 | K37: Pangestu Widodo | L37: Teknik Komputer | M37: 0
A38: 35 | B38: Hawwin Mardhiana | C38: Hawwin | D38: Mardhiana | F38: Sistem Informasi | G38: Fakultas Rekayasa Industri | H38: 4 | J38: 35 | K38: Abduh Sayid Albana | L38: Teknik Logistik | M38: 69
A39: 36 | B39: Benazir Imam Arif Muttaqin | C39: Benazir | D39: Imam | E39: Muttaqin | F39: Teknik Industri | G39: Fakultas Rekayasa Industri | H39: 16 | J39: 36 | K39: Hawwin Mardhiana | L39: Sistem Informasi | M39: 4
A40: 37 | B40: Bernadus Anggo Seno Aji | C40: Bernadus | D40: Anggo | E40: Aji | F40: Teknologi Informasi | G40: Fakultas Informatika | H40: 9 | J40: 37 | K40: Benazir Imam Arif Muttaqin | L40: Teknik Industri | M40: 20
A41: 38 | B41: Rokhmatul Insani | C41: Rokhmatul | D41: Insani | F41: Sistem Informasi | G41: Fakultas Rekayasa Industri | H41: 7 | J41: 38 | K41: Bernadus Anggo Seno Aji | L41: Teknologi Informasi | M41: 10
...

Sheet Grafik PNLT
A2: Tahun Usulan | B2: 2024
A4: Nama Skema | B4: Count of Nama Skema
A5: PENELITIAN DASAR PERIODE 1 | B5: 29
A6: PENELITIAN DASAR PERIODE 2 | B6: 7
A7: PENELITIAN KEMITRAAN DALAM NEGERI PERIODE 1 | B7: 1
A8: PENELITIAN KEMITRAAN LUAR NEGERI PERIODE 1 | B8: 1
A9: PENELITIAN MANDIRI PERIODE 1 | B9: 3
A10: PENELITIAN STRATEGIS PERIODE 1 | B10: 3
A11: PENELITIAN TERAPAN PERIODE 1 | B11: 3
A12: Grand Total | B12: 47
A45: SDG | B45: Count of SDG
A46: 2 | B46: 1
A47: 3 | B47: 4
A48: 4 | B48: =4+E52 -> 4
A49: 5 | B49: 1
A50: 6 | B50: 1
A51: 7 | B51: =1+E49 -> 1
A52: 8 | B52: =1+E50 -> 1
A53: 9 | B53: =9+E46 -> 9
A54: 11 | B54: 1
A55: 14 | B55: 1
A56: 17 | B56: =1+E47 -> 1
A57: 13 | B57: 2
A58: 16 | B58: 2
A59: 12 | B59: 1
A60: 11 | B60: 1
B61: =SUM(B46:B60) -> 31

Sheet Grafik SDG PNLT
A1: Tahun Usulan | B1: 2024-2025 | E1: Tahun Usulan | F1: 2024
A3: SDG | B3: Keterangan | C3: Jumlah | E3: SDG | F3: Keterangan | G3: Jumlah
A4: 1 | B4: Tanpa Kemiskinan | C4: =COUNTIF(#REF!,"1") -> #REF! | E4: 1 | F4: Tanpa Kemiskinan | G4: =COUNTIF(#REF!,"1") -> #REF!
A5: 2 | B5: Tanpa Kelaparan | C5: =COUNTIF(#REF!,"2") -> #REF! | E5: 2 | F5: Tanpa Kelaparan | G5: =COUNTIF(#REF!,"2") -> #REF!
A6: 3 | B6: Kehidupan Sehat dan Sejahtera | C6: =COUNTIF(#REF!,"3") -> #REF! | E6: 3 | F6: Kehidupan Sehat dan Sejahtera | G6: =COUNTIF(#REF!,"3") -> #REF!
A7: 4 | B7: Pendidikan Berkualitas | C7: =COUNTIF(#REF!,"4") -> #REF! | E7: 4 | F7: Pendidikan Berkualitas | G7: =COUNTIF(#REF!,"4") -> #REF!
A8: 5 | B8: Kesetaraan Gender | C8: =COUNTIF(#REF!,"5") -> #REF! | E8: 5 | F8: Kesetaraan Gender | G8: =COUNTIF(#REF!,"5") -> #REF!
A9: 6 | B9: Air Bersih dan Sanitasi Layak | C9: =COUNTIF(#REF!,"6") -> #REF! | E9: 6 | F9: Air Bersih dan Sanitasi Layak | G9: =COUNTIF(#REF!,"6") -> #REF!
A10: 7 | B10: Energi Bersih dan Terjangkau | C10: =COUNTIF(#REF!,"7") -> #REF! | E10: 7 | F10: Energi Bersih dan Terjangkau | G10: =COUNTIF(#REF!,"7") -> #REF!
A11: 8 | B11: Pekerjaan Layak dan Pertumbuhan Ekonomi | C11: =COUNTIF(#REF!,"8") -> #REF! | E11: 8 | F11: Pekerjaan Layak dan Pertumbuhan Ekonomi | G11: =COUNTIF(#REF!,"8") -> #REF!
A12: 9 | B12: Industri, Inovasi dan Infrastruktur | C12: =COUNTIF(#REF!,"9") -> #REF! | E12: 9 | F12: Industri, Inovasi dan Infrastruktur | G12: =COUNTIF(#REF!,"9") -> #REF!
A13: 10 | B13: Berkurangnya Kesenjangan | C13: =COUNTIF(#REF!,"10") -> #REF! | E13: 10 | F13: Berkurangnya Kesenjangan | G13: =COUNTIF(#REF!,"10") -> #REF!
A14: 11 | B14: Kota dan Permukiman yang Berkelanjutan | C14: =COUNTIF(#REF!,"11") -> #REF! | E14: 11 | F14: Kota dan Permukiman yang Berkelanjutan | G14: =COUNTIF(#REF!,"11") -> #REF!
A15: 12 | B15: Konsumsi dan Produksi yang Bertanggung Jawab | C15: =COUNTIF(#REF!,"12") -> #REF! | E15: 12 | F15: Konsumsi dan Produksi yang Bertanggung Jawab | G15: =COUNTIF(#REF!,"12") -> #REF!
A16: 13 | B16: Penanganan Perubahan Iklim | C16: =COUNTIF(#REF!,"13") -> #REF! | E16: 13 | F16: Penanganan Perubahan Iklim | G16: =COUNTIF(#REF!,"13") -> #REF!
A17: 14 | B17: Ekosistem Lautan | C17: =COUNTIF(#REF!,"14") -> #REF! | E17: 14 | F17: Ekosistem Lautan | G17: =COUNTIF(#REF!,"14") -> #REF!
A18: 15 | B18: Ekosistem Daratan | C18: =COUNTIF(#REF!,"15") -> #REF! | E18: 15 | F18: Ekosistem Daratan | G18: =COUNTIF(#REF!,"15") -> #REF!
A19: 16 | B19: Perdamaian, Keadilan, dan Kelembagaan yang Tangguh | C19: =COUNTIF(#REF!,"16") -> #REF! | E19: 16 | F19: Perdamaian, Keadilan, dan Kelembagaan yang Tangguh | G19: =COUNTIF(#REF!,"16") -> #REF!
A20: 17 | B20: Kemitraan untuk Mencapai Tujuan | C20: =COUNTIF(#REF!,"17") -> #REF! | E20: 17 | F20: Kemitraan untuk Mencapai Tujuan | G20: =COUNTIF(#REF!,"17") -> #REF!
E23: Tahun Usulan | F23: 2025
E25: SDG | F25: Keterangan | G25: Jumlah
E26: 1 | F26: Tanpa Kemiskinan | G26: =COUNTIF(#REF!,"1") -> #REF!
E27: 2 | F27: Tanpa Kelaparan | G27: =COUNTIF(#REF!,"2") -> #REF!
E28: 3 | F28: Kehidupan Sehat dan Sejahtera | G28: =COUNTIF(#REF!,"3") -> #REF!
E29: 4 | F29: Pendidikan Berkualitas | G29: =COUNTIF(#REF!,"4") -> #REF!
E30: 5 | F30: Kesetaraan Gender | G30: =COUNTIF(#REF!,"5") -> #REF!
E31: 6 | F31: Air Bersih dan Sanitasi Layak | G31: =COUNTIF(#REF!,"6") -> #REF!
E32: 7 | F32: Energi Bersih dan Terjangkau | G32: =COUNTIF(#REF!,"7") -> #REF!
E33: 8 | F33: Pekerjaan Layak dan Pertumbuhan Ekonomi | G33: =COUNTIF(#REF!,"8") -> #REF!
E34: 9 | F34: Industri, Inovasi dan Infrastruktur | G34: =COUNTIF(#REF!,"9") -> #REF!
E35: 10 | F35: Berkurangnya Kesenjangan | G35: =COUNTIF(#REF!,"10") -> #REF!
E36: 11 | F36: Kota dan Permukiman yang Berkelanjutan | G36: =COUNTIF(#REF!,"11") -> #REF!
E37: 12 | F37: Konsumsi dan Produksi yang Bertanggung Jawab | G37: =COUNTIF(#REF!,"12") -> #REF!
E38: 13 | F38: Penanganan Perubahan Iklim | G38: =COUNTIF(#REF!,"13") -> #REF!
E39: 14 | F39: Ekosistem Lautan | G39: =COUNTIF(#REF!,"14") -> #REF!
E40: 15 | F40: Ekosistem Daratan | G40: =COUNTIF(#REF!,"15") -> #REF!
E41: 16 | F41: Perdamaian, Keadilan, dan Kelembagaan yang Tangguh | G41: =COUNTIF(#REF!,"16") -> #REF!
E42: 17 | F42: Kemitraan untuk Mencapai Tujuan | G42: =COUNTIF(#REF!,"17") -> #REF!

Sheet Grafik PKM
A1: Tahun Usulan | B1: 2024
A3: Nama Skema | B3: Count of Nama Skema
A4: KOLABORASI DALAM NEGERI | B4: 5
A5: PENDAMPINGAN/PELATIHAN PERIODE 1 | B5: 5
A6: PENDAMPINGAN/PELATIHAN PERIODE 2 | B6: 1
A7: TEKNOLOGI TEPAT GUNA (TTG) PERIODE 1 | B7: 16
A8: TEKNOLOGI TEPAT GUNA (TTG) PERIODE 2 | B8: 5
A9: Grand Total | B9: 32

Sheet Grafik SDG PKM
A1: Tahun Pelaksanaan Kegiatan | B1: 2024
A3: SDG | B3: Count of SDG
A4: 1 | B4: 2
A5: 2 | B5: 4
A6: 3 | B6: 10
A7: 4 | B7: 7
A8: 5 | B8: 1
A9: 6 | B9: 5
A10: 7 | B10: 2
A11: 9 | B11: 1
A12: Grand Total | B12: 32

Sheet Publikasi implementasi
A1: DATA PUBLIKASI | I1: DATA PENULIS KORESPONDING | N1: DATA PENULIS (1) | S1: DATA PENULIS (2) | X1: DATA PENULIS (3) | AC1: DATA PENULIS (4) | AH1: DATA PENULIS (5) | AM1: DATA PENULIS (6) | AR1: DATA PENULIS LAINNYA
A2: Judul Publikasi | B2: Nama Jurnal | C2: Implementasi | D2: Akreditasi/ Index Jurnal | E2: Lembaga Pengindeks | F2: Tahun Submit | G2: Tahun Accepted | H2: Tahun Published | I2: Nama Penulis Koresponding | J2: Sinta ID | K2: NIDN | L2: Prodi | M2: Afiliasi | N2: Nama Penulis (1) | O2: Prodi2 | P2: Afiliasi3 | Q2: Sinta ID4 | R2: NIDN5 | S2: Nama Penulis (2) | T2: Prodi6 | U2: Afiliasi7 | V2: Sinta ID8 | W2: NIDN9 | X2: Nama Penulis (3) | Y2: Prodi10 | Z2: Afiliasi11 | AA2: Sinta ID12 | AB2: NIDN13 | AC2: Nama Penulis (4) | AD2: Prodi14 | AE2: Afiliasi15 | AF2: Sinta ID16 | AG2: NIDN17 | AH2: Nama Penulis (5) | AI2: Prodi18 | AJ2: Afiliasi19 | AK2: Sinta ID20 | AL2: NIDN21 | AM2: Nama Penulis (6) | AN2: Prodi22 | AO2: Afiliasi23 | AP2: Sinta ID24 | AQ2: NIDN25 | AR2: Nama Penulis Lain | AS2: Prodi26 | AT2: Afiliasi27 | AU2: Sinta ID28 | AV2: NIDN29
A3: Low-cost Transverse Electromagnetic (TEM) cell design for radiated emission measurement | B3: IOP Conference Series: Materials Science and Engineering 1073 (1), 012040, 2021 | D3: Prosiding Internasional | H3: 2021 | I3: Muhammad Yanuar Hariawan | L3: TK | M3: ITTELKOM Surabaya | N3: Muhammad Yanuar Hariawan | O3: TK | P3: ITTELKOM Surabaya | S3: Rizadi Sasmita Darwis | U3: Politeknik Caltex Riau | X3: B A Habibi | Z3: Politeknik Caltex Riau
A4: Simulasi Efisiensi dan Akurasi Shielding Effectiveness pada Kabel Coaxial | B4: ABEC Indonesia 9, 1263-1274, 2021 | D4: Prosiding Nasional | H4: 2021 | I4: Putri Cahyanda | M4: Politeknik Caltex Riau | N4: Putri Cahyanda | P4: Politeknik Caltex Riau | S4: Rizadi Sasmita Darwis | U4: Politeknik Caltex Riau | X4: Muhammad Yanuar Hariawan | Y4: TK | Z4: ITTELKOM Surabaya
A5: RANCANG MAGNETIC NEAR FIELD PROBE UNTUK PENGUJIAN RADIATED EMISSION PADA FREKUENSI RENDAH | B5: ABEC Indonesia 9, 1040-1049, 2021 | D5: Prosiding Nasional | H5: 2021 | I5: Yospet Pradika | M5: Politeknik Caltex Riau | N5: Yospet Pradika | P5: Politeknik Caltex Riau | S5: Muhammad Yanuar Hariawan | T5: TK | U5: ITTELKOM Surabaya
A6: RANCANG BANGUN ALAT MONITORING KUALITAS UDARA BERBASIS NODEMCU ESP8266 (HARDWARE) | B6: ABEC Indonesia 9, 837-846, 2021 | D6: Prosiding Nasional | H6: 2021 | I6: Raywanda Affandi Harahap | M6: Politeknik Caltex Riau | N6: Raywanda Affandi Harahap | P6: Politeknik Caltex Riau | S6: Muhammad Yanuar Hariawan | T6: TK | U6: ITTELKOM Surabaya
A7: Filter EMI Aktif menggunakan Op-Amp untuk Mereduksi Near-Field EMI pada PCB | B7: ABEC Indonesia 9, 847-856, 2021 | D7: Prosiding Nasional | H7: 2021 | I7: Wahyudi Nasrianza1 | M7: Politeknik Caltex Riau | N7: Wahyudi Nasrianza1 | P7: Politeknik Caltex Riau | S7: Muhammad Yanuar Hariawan | T7: TK | U7: ITTELKOM Surabaya
A8: SISTEM MONITORING KUALITAS UDARA BERBASIS NODEMCU ESP8266 DENGAN METODE FUZZY LOGIC (SOFTWARE) | B8: ABEC Indonesia 9, 1050-1062, 2021 | D8: Prosiding Nasional | H8: 2021 | I8: Diemas Ibnus Pasedja | M8: Politeknik Caltex Riau | N8: Diemas Ibnus Pasedja | P8: Politeknik Caltex Riau | S8: Muhammad Yanuar Hariawan | T8: TK | U8: ITTELKOM Surabaya
A9: Pengaruh Ketebalan Material Terhadap Shielding effectiveness pada Frekuensi Rendah | B9: Jurnal Elektro dan Mesin Terapan 7 (2), 18-24, 2021 | D9: S4 | E9: SINTA | H9: 2021 | I9: Muhammad Yanuar Hariawan | L9: TK | M9: ITTELKOM Surabaya | N9: Muhammad Yanuar Hariawan | O9: TK | P9: ITTELKOM Surabaya | S9: Rizadi Sasmita Darwis | U9: Politeknik Caltex Riau
A10: Prediksi Jarak Bola Pada Citra Kamera Katadioptrik Menggunakan Metode Artifical Neural Network | B10: ELKOMIKA: Jurnal Teknik Energi Elektrik, Teknik Telekomunikasi, &amp; Teknik Elektronika | D10: S2 | E10: SINTA | H10: 2021 | I10: ZENDI ZAKARIA RAGA PERMANA | M10: Universitas Dinamika | N10: ZENDI ZAKARIA RAGA PERMANA | P10: Universitas Dinamika | S10: Susijanto Tri Rasmana | T10: TE | U10: ITTELKOM Surabaya | X10: IRA PUSPASARI | Z10: Universitas Dinamika
A11: A Systematic Review on the Autonomous Emergency Steering Assessments and Tests Methodology in ASEAN | B11: Journal of the Society of Automotive Engineers Malaysia 5 (2), 185-193, 2021 | D11: Jurnal ber-ISSN | H11: 2021 | I11: M.A.Abdul Rahman | M11: UTM | N11: Susijanto Tri Rasmana | O11: TE | P11: ITTELKOM Surabaya | S11: Dimas Adiputra | T11: TE | U11: ITTELKOM Surabaya | X11: M.A.Abdul Rahman | Z11: UTM | AC11: A.Dwijotomo | AE11: UTM | AH11: M.H.Mohammed Ariff | AJ11: UTM | AM11: N.Abu Husain | AO11: UTM
A12: Pengendali Tingkat Keasaman Air Kolam untuk Peternak Ikan Lele | B12: JMM (Jurnal Masyarakat Mandiri) 5 (6), 3135-3144, 2021 | D12: S3 | E12: SINTA | H12: 2021 | N12: Susijanto Tri Rasmana | O12: TE | P12: ITTELKOM Surabaya | S12: Mochammad Iskandar Riansyah | T12: TE | U12: ITTELKOM Surabaya | X12: Chaironi Latif | Y12: TE | Z12: ITTELKOM Surabaya | AC12: Muhammad Dwi Hariyanto | AD12: TE | AE12: ITTELKOM Surabaya | AH12: Anak Agung Kusuma Jaya Ningrat | AI12: TE | AJ12: ITTELKOM Surabaya | AM12: Jesica Febriani Nura | AN12: TE | AO12: ITTELKOM Surabaya
A13: KINERJA KARYAWAN (KONSEP PENILAIAN KINERJA DI PERUSAHAAN) | B13: CV WIDINA MEDIA UTAMA, 2021 | D13: Buku | H13: 2021 | N13: Hartini Hartini | S13: Alnisa Min Fadlillah | X13: Hetty Ismainar | AC13: Retno Setyorini | AH13: Ahmad Bairizki | AM13: Afdol Muftiasa | AR13: Titus Kristanto | AS13: RPL | AT13: ITTELKOM Surabaya
A14: Kewirausahaan (Teori dan Praktis) | B14: CV WIDINA MEDIA UTAMA, 2021 | D14: Buku | H14: 2021 | N14: Agus Alimuddin | S14: Adih Supriadi | X14: Ujang Enas | AC14: Fauzan Aziz | AH14: Komang Trisna Sari Dewi | AM14: Nikmatul Khoiriyah | AR14: Titus Kristanto | AS14: RPL | AT14: ITTELKOM Surabaya
A15: Marketing Digital Usaha Mikro | B15: CV WIDINA MEDIA UTAMA, 2021 | D15: Buku | H15: 2021 | N15: Rudy Irwansyah | S15: Danil Syahputra | X15: Supiah Ningsih | AC15: Muhammad Hasan | AH15: Titus Kristanto | AI15: RPL | AJ15: ITTELKOM Surabaya | AM15: Lucky Nugroho | AR15: Diana Triwardhani
A16: Pelatihan Dan Pendampingan Pemasaran Online Produk Nasi Tiwul Di Masa Pandemi Covid-19 | B16: JMM (Jurnal Masyarakat Mandiri) 5 (4), 1681-1688, 2021 | D16: S3 | E16: SINTA | H16: 2021 | N16: Titus Kristanto | O16: RPL | P16: ITTELKOM Surabaya | S16: Dewi Rahmawati | T16: RPL | U16: ITTELKOM Surabaya | X16: Ayu Endah Wahyuni | Y16: TI | Z16: ITTELKOM Surabaya | AC16: Muhammad Nasrullah | AD16: SI | AE16: ITTELKOM Surabaya | AH16: Reza Arindra Fadillah | AI16: RPL | AJ16: ITTELKOM Surabaya | AM16: Amanda Amalia | AN16: RPL | AO16: ITTELKOM Surabaya
A17: PELATIHAN PENINGKATAN KEMAMPUAN MENGGUNAKAN MICROSOFT DYNAMICS 365 BUSINESS CENTRAL | B17: Prosiding Konferensi Nasional Pengabdian Kepada Masyarakat dan Corporate &#8230;, 2021 | D17: Prosiding Nasional | H17: 2021 | I17: Muhammad Nasrullah | L17: SI | M17: ITTELKOM Surabaya | N17: Muhammad Nasrullah | O17: SI | P17: ITTELKOM Surabaya | S17: Titus Kristanto | T17: RPL | U17: ITTELKOM Surabaya
A18: Pengujian Black Box Menggunakan Teknik Equivalence Partitions Pada Aplikasi E-Learning Berbasis Web | B18: Building of Informatics, Technology and Science (BITS) 3 (3), 269-274, 2021 | D18: S3 | E18: SINTA | H18: 2021 | I18: Titus Kristanto | L18: RPL | M18: ITTELKOM Surabaya | N18: Titus Kristanto | O18: RPL | P18: ITTELKOM Surabaya | S18: Amanda Amalia | U18: ITTELKOM Surabaya | X18: Salva Wanda Putri Hamidah | Z18: ITTELKOM Surabaya
A19: PENGARUH KREATIVITAS DAN MOTIVASI TERHADAP KARAKTERISTIK KINERJA MANAJERIAL PT PAL INDONESIA (PERSERO) MENGGUNAKAN METODE GRAPHIC RATING SCALE | B19: Prosiding Seminar Nasional MIPATI 1 (1), 2021 | D19: Prosiding Nasional | H19: 2021 | N19: Titus Kristanto | O19: RPL | P19: ITTELKOM Surabaya | S19: Rosdiana Marpaung | U19: Sekolah Tinggi Ilmu Ekonomi Indonesia | X19: Dwi Mustika Kusumawardani | Z19: ITTP | AC19: Dewi Rahmawati | AD19: RPL | AE19: ITTELKOM Surabaya
A20: EndorseGram: Interactive Visualization of Influencer Endorsement Marketplace | B20: 2021 International Conference on Computer Science, Information Technology and Electrical Engineering (ICOMITEE), 2021 | D20: Prosiding Internasional | H20: 2021 | N20: Mochamad Nizar Palefi Ma’Ady | O20: SI | P20: ITTELKOM Surabaya | S20: Shinta Amalia Kusuma Wardhani | U20: Universitas Nahdlatul Ulama Sunan Giri
A21: EFFECTIVE MANAGEMENT OF ONLINE LEARNING DURING PANDEMIC AT SDN 1 TANAH TINGGI | B21: PROGRES PENDIDIKAN 2 (2), 115-118, 2021 | D21: S5 | E21: SINTA | H21: 2021 | I21: Ina Magdalena | M21: Universitas Muhammadiyah Tangerang | N21: Ina Magdalena | P21: Universitas Muhammadiyah Tangerang | S21: Ayu Endah Wahyuni | T21: TI | U21: ITTELKOM Surabaya | X21: Davina Dewi Hartana | Z21: Universitas Muhammadiyah Tangerang
A22: The Development of TRAM Model for Blockchain Use Readiness Among MSMEs in Indonesia | B22: Ninth International Conference on Entrepreneurship and Business Management (ICEBM 2020) | D22: Prosiding Internasional | H22: 2021 | I22: Ayu Endah Wahyuni | L22: TI | M22: ITTELKOM Surabaya | N22: Ayu Endah Wahyuni | O22: TI | P22: ITTELKOM Surabaya | S22: Anita Juraida | U22: Universitas Widyatama | X22: Asep Anwar | Z22: Universitas Widyatama
A23: Readiness factor identification Bandung city MSMEs use blockchain technology | B23: Jurnal Sistem dan Manajemen Industri 5 (2), 53-62, 2021 | D23: S2 | E23: SINTA | H23: 2021 | I23: Ayu Endah Wahyuni | L23: TI | M23: ITTELKOM Surabaya | N23: Ayu Endah Wahyuni | O23: TI | P23: ITTELKOM Surabaya | S23: Anita Juraida | U23: Universitas Widyatama | X23: Asep Anwar | Z23: Universitas Widyatama
A24: Pembuatan Film Animasi Permainan Tradisional Anak-Anak Berbasis 3 Dimensi | B24: eProceeding of TIK 1 (1), 2021 | D24: Jurnal ber-ISSN | H24: 2021 | I24: Ayu Endah Wahyuni | L24: TI | M24: ITTELKOM Surabaya | N24: Ayu Endah Wahyuni | O24: TI | P24: ITTELKOM Surabaya | S24: Mursyidah | U24: Politeknik Negeri Lhokseumawe | X24: Muhammad Nasir | Z24: Politeknik Negeri Lhokseumawe
A25: PEMBUATAN WORKBENCH ERGONOMIS UNTUK MENDUKUNG AKTIVITAS PEMILAHAN, PENGEPRESAN, DAN PENGARUNGAN SAMPAH AIR MINUM DALAM KEMASAN DI KELURAHAN WONKUSUMO SURABAYA | B25: LOGISTA-Jurnal Ilmiah Pengabdian kepada Masyarakat 5 (2), 330-335, 2021 | D25: S4 | E25: SINTA | H25: 2021 | N25: Rahaditya Dimas Prihadianto | O25: TI | P25: ITTELKOM Surabaya | S25: Abduh Sayid Albana | T25: TI | U25: ITTELKOM Surabaya | X25: Ayu Endah Wahyuni | Y25: TI | Z25: ITTELKOM Surabaya | AC25: Hendrawan Widianto | AD25: TI | AE25: ITTELKOM Surabaya
A26: MENGGAGAS MEJA DIGITAL PRIBADI (DIGITALLY PERSONALIZED DESKS) UNTUK ANAK USIA DINI DALAM SISTEM PEMBELAJARAN | B26: Lomba Karya Tulis Ilmiah 2 (1), 109-114, 2021 | D26: Jurnal tidak ber-ISSN | H26: 2021 | N26: Amarrangga Kumara Prada | P26: ITTELKOM Surabaya | S26: Iftitah Kurnia | U26: ITTELKOM Surabaya | X26: Mohammad Robi Maulana | Z26: ITTELKOM Surabaya | AC26: Ayu Endah Wahyuni | AD26: TI | AE26: ITTELKOM Surabaya
A27: Fuzzy Gain Scheduling for Cascaded PI-Control for DC Motor | B27: 2021 IEEE Conference on Energy Conversion (CENCON), 158-162, 2021 | D27: Prosiding Internasional | H27: 2021 | N27: Deany Putri Aulia | P27: Universitas Pertamina | S27: Alfiyah Shaldzabila Yustin | U27: Universitas Pertamina | X27: Amien Marzuq Hilman | Z27: Universitas Pertamina | AC27: Aulia Rahma Annisa | AD27: TK | AE27: ITTELKOM Surabaya | AH27: Eng Wahyu Kunto Wibowo | AJ27: Universitas Pertamina
A28: Rancang Bangun Sistem Alat Fototerapi Untuk Bayi Hiperbilirubinemia Berbasis Internet Of Things (IoT) | B28: Kilat 11 (2), 111-188, 2022 | D28: S4 | E28: SINTA | H28: 2021 | I28: Annida Sakinah Ramadhani | M28: Universitas Pertamina | N28: Annida Sakinah Ramadhani | P28: Universitas Pertamina | S28: Herminarto Nugroho | U28: Universitas Pertamina | X28: Aulia Rahma Annisa | Y28: TK | Z28: ITTELKOM Surabaya
A29: Implementasi Virtual Reality Berbasis Foto 360o Untuk Memvisualisasikan Fasilitas Perguruan Tinggi Surabaya | B29: Jurnal RESTI (Rekayasa Sistem Dan Teknologi Informasi) 5 (1), 155-162, 2021 | D29: S2 | E29: SINTA | H29: 2021 | I29: Nadiah Ratnaduhita | L29: SI | M29: ITTELKOM Surabaya | N29: Nadiah Ratnaduhita | O29: SI | P29: ITTELKOM Surabaya | S29: Ian Mahendra Putra | T29: SI | U29: ITTELKOM Surabaya | X29: Ully Asfari | Y29: SI | Z29: ITTELKOM Surabaya | AC29: Yupit Sudianto | AD29: SI | AE29: ITTELKOM Surabaya | AH29: Benazir Imam Arif Muttaqin | AI29: TI | AJ29: ITTELKOM Surabaya
A30: Modeling of salt supply chains to achieve competitive salt prices | B30: International Journal on Food System Dynamics 12 (1), 51-67, 2021 | D30: Q2 | H30: 2021 | N30: Isnaini Muhandhis | P30: Universitas Wijaya Putra | S30: Budisantoso Wirjodirdjo | U30: ITS | X30: Erma Suryani | Z30: ITS | AC30: Heri Susanto | AE30: Universitas Wijaya Putra | AH30: Ully Asfari | AI30: SI | AJ30: ITTELKOM Surabaya
A31: System Dynamic Framework: Increasing Productivity Of Sugarcane To Support Sustainable Cultivation | B31: Sustainability in Food and Agriculture (SFNA) 2 (2), 105-109, 2021 | D31: Jurnal ber-ISSN | H31: 2021 | I31: Hawwin Mardhiana | L31: SI | M31: ITTELKOM Surabaya | N31: Hawwin Mardhiana | O31: SI | P31: ITTELKOM Surabaya | S31: Erma Suryani | U31: ITS | X31: Ully Asfari | Y31: SI | Z31: ITTELKOM Surabaya | AC31: Muhammad Nasrullah | AD31: SI | AE31: ITTELKOM Surabaya
A32: 3D Virtual prototyping dalam Perbaikan Desain Fasilitas Tempat Kerja: Studi Kasus CV. XYZ | B32: Jurnal IPTEK 25 (1), 69-76, 2021 | D32: S3 | E32: SINTA | H32: 2021 | N32: Benazir Imam Arif Muttaqin | O32: TI | P32: ITTELKOM Surabaya | S32: Ully Asfari | T32: SI | U32: ITTELKOM Surabaya | X32: Hawwin Mardhiana | Y32: SI | Z32: ITTELKOM Surabaya | AC32: Shanggabuana Adhitya Shamaradewa | AD32: TI | AE32: ITTELKOM Surabaya | AH32: Gagas Putra Dawangga | AI32: SI | AJ32: ITTELKOM Surabaya
A33: Faktor yang Mempengaruhi Implementasi Green Human Resource Management pada Ormawa: Model Konseptual: Indonesia | B33: Journal of Advances in Information and Industrial Technology 3 (1), 11-18, 2021 | D33: Jurnal ber-ISSN | H33: 2021 | I33: Moch. Yusuf Fathussalam | L33: SI | M33: ITTELKOM Surabaya | N33: Moch. Yusuf Fathussalam | O33: SI | P33: ITTELKOM Surabaya | S33: I G Ag Kom Agnam M | T33: SI | U33: ITTELKOM Surabaya | X33: Irene Dyah Ayuwati | Y33: SI | Z33: ITTELKOM Surabaya | AC33: Desy Fitri A. L. | AD33: SI | AE33: ITTELKOM Surabaya | AH33: Yuniar Revi A. L | AI33: SI | AJ33: ITTELKOM Surabaya | AM33: Geraldo Brata Hiroshi P. | AN33: SI | AO33: ITTELKOM Surabaya | AR33: Ully Asfari | AS33: SI | AT33: ITTELKOM Surabaya
A34: Pengaruh Pelatihan dan Pengembangan SDM Pada ABA Collection Terhadap Kinerja Pegawai Menggunakan Metode Regresi Linear Berganda | B34: Journal of Advances in Information and Industrial Technology 3 (1), 19-30, 2021 | D34: Jurnal ber-ISSN | H34: 2021 | I34: Nadiah Ratnaduhita | L34: SI | M34: ITTELKOM Surabaya | N34: Nadiah Ratnaduhita | O34: SI | P34: ITTELKOM Surabaya | S34: Rio Armando | T34: SI | U34: ITTELKOM Surabaya | X34: Salsabila Qatrunnada | Y34: SI | Z34: ITTELKOM Surabaya | AC34: Tanang Satriyo Adi | AD34: SI | AE34: ITTELKOM Surabaya | AH34: Tanfirul Roibafi | AI34: SI | AJ34: ITTELKOM Surabaya | AM34: Wan Azizah Sri Nuraini | AN34: SI | AO34: ITTELKOM Surabaya | AR34: Ully Asfari | AS34: SI | AT34: ITTELKOM Surabaya
A35: INOVASI KINERJA PRODUKSI KOPI UNTUK MENINGKATKAN KEUNTUNGAN MELALUI KEGIATAN PENGABDIAN MASYARAKAT KE UKM KOPI ARABICA TRADISIONAL | B35: Prosiding Seminar Nasional &amp; Call for Paper&quot; Peran Perempuan Sebagai &#8230;, 2021 | D35: Prosiding Nasional | H35: 2021 | N35: Ully Asfari | O35: SI | P35: ITTELKOM Surabaya | S35: Isnaini Muhandhis | U35: Universitas Wijaya Putra | X35: Imam Kholik | Z35: Universitas Wijaya Putra
A36: Edge Computing Based Pickup and Delivery Optimization for Warehouse | B36: KICS Winter Conference 2021, 323-324, 2021 | D36: Prosiding Internasional | H36: 2021 | N36: Philip Tobianto Daely | O36: IT | P36: ITTELKOM Surabaya | S36: Jae-Woo Kim | U36: Kumoh National Institute of Technology | X36: Jae Min Lee | Z36: Kumoh National Institute of Technology | AC36: Dong-Seong Kim | AE36: Kumoh National Institute of Technology
A37: Dynamic VRP optimization using discrete PSO in edge computing environment | B37: 2021 International Conference on Information and Communication Technology Convergence (ICTC);, 2021 | D37: Prosiding Internasional | H37: 2021 | N37: Philip Tobianto Daely | O37: IT | P37: ITTELKOM Surabaya | S37: Yohana Jayanti Aruan | U37: Kumoh National Institute of Technology | X37: Jae Min Lee | Z37: Kumoh National Institute of Technology | AC37: Dong-Seong Kim | AE37: Kumoh National Institute of Technology
A38: The design of the emerging 5g using hybrid gpon and xgs-pon technology | B38: 2022 International Conference on Information and Communication Technology Convergence (ICTC);, 2021 | D38: Prosiding Internasional | H38: 2021 | N38: Yohana Jayanti Aruan | P38: Kumoh National Institute of Technology | S38: Philip Tobianto Daely | T38: IT | U38: ITTELKOM Surabaya | X38: Gabriel Avelino Ramos Sampedro | Z38: Kumoh National Institute of Technology | AC38: Jae Min Lee | AE38: Kumoh National Institute of Technology | AH38: Dong-Seong Kim | AJ38: Kumoh National Institute of Technology
A39: Battery Insulation Performance Analysis in Electric Vehicles for the Improvement of Battery Lifetime | B39: Jurnal Ilmiah Teknik Elektro Komputer dan Informatika (JITEKI) 7 (3), 412-422, 2021 | D39: S2 | E39: SINTA | H39: 2021 | I39: Lora Khaula Amifia | L39: TE | M39: ITTELKOM Surabaya | N39: Lora Khaula Amifia | O39: TE | P39: ITTELKOM Surabaya | S39: Nuansa Dipa Bismoko | U39: PT. Telekomunikasi Seluler | X39: Philip Tobianto Daely | Y39: IT | Z39: ITTELKOM Surabaya
A40: Prediction Point of Fault Location on Its Campus Power Grid by using Neural Artificial Method | B40: IOP Conference Series: Materials Science and Engineering 1096 (1), 012068, 2021 | D40: Prosiding Internasional | H40: 2021 | I40: A Syamsudin | M40: ITS | N40: A Syamsudin | P40: ITS | S40: Isa Hafidz | T40: TE | U40: ITTELKOM Surabaya | X40: D Rahmatullah | Z40: Universitas Hang Tuah | AC40: D A Asfani | AE40: ITS | AH40: I M Y Negara | AJ40: ITS
...

Sheet Pivot Publikasi
A1: Tahun Published | B1: 2025
A2: Lembaga Pengindeks | B2: (Beberapa Item)
A4: Akreditasi/ Index Jurnal | B4: Count of Akreditasi/ Index Jurnal
A5: Jurnal ber-ISSN | B5: 2
A6: S2 | B6: 2
A7: S3 | B7: 13
A8: S4 | B8: 10
A9: S5 | B9: 3
A10: S6 | B10: 1
A11: (kosong)
A12: Total Keseluruhan | B12: 31

Sheet Pivot Data KI
A1: APPLICATION YEAR | B1: 2025
A3: Count of Kategori | C3: Status
A4: Kategori | B4: Jenis HKI | C4: (PA) Diberi Paten | D4: Granted | E4: (PA) Pemeriksaan Formalitas | F4: Grand Total
A5: Hak Cipta | B5: Karya Lainnya (Program Komputer) | D5: 58 | F5: 58
B6: Karya Tulis | D6: 33 | F6: 33
B7: Buku Panduan/Petunjuk | D7: 1 | F7: 1
B8: Karya Rekaman Video | D8: 1 | F8: 1
B9: Modul | D9: 1 | F9: 1
A10: Hak Cipta Total | D10: 94 | F10: 94
A11: Paten | B11: Alat / Sistem | E11: 1 | F11: 1
A12: Paten Total | E12: 1 | F12: 1
A13: Paten Sederhana | B13: Alat / Sistem | C13: 2 | F13: 2
B14: Metode | C14: 3 | E14: 4 | F14: 7
A15: Paten Sederhana Total | C15: 5 | E15: 4 | F15: 9
A16: DESAIN INDUSTRI | B16: Satu Kesatuan Desain (Set) | E16: 1 | F16: 1
A17: DESAIN INDUSTRI Total | E17: 1 | F17: 1
A18: Grand Total | C18: 5 | D18: 94 | E18: 6 | F18: 105

Sheet Program start Up
A2: No | B2: Prodi | C2: Nama Tim | D2: Kategori Program
A3: 1 | B3: Digital Bisnis | C3: Kustompedia | D3: Faculty Joint Incubation Program (FJIP)
A4: 2 | B4: Teknik Industri | C4: Etechting | D4: Faculty Joint Incubation Program (FJIP)
A5: 3 | B5: Teknik Komputer | C5: EsTehAnget | D5: Faculty Joint Incubation Program (FJIP)
A6: 4 | B6: Teknik Komputer | C6: LokaThings | D6: Faculty Joint Incubation Program (FJIP)
A7: 5 | B7: Sistem Informasi | C7: Devinit | D7: WRAP Entrepreneurship
A8: 6 | B8: Informatika | C8: Solusi Ketenagakerjaan | D8: WRAP Entrepreneurship
A9: 7 | B9: Informatika | C9: Berdaya | D9: WRAP Entrepreneurship
A10: 8 | B10: Digital Bisnis | C10: Mesti Minum | D10: WRAP Entrepreneurship
A11: 9 | B11: Informatika | C11: Sistem Informasi Koperasi | D11: WRAP Entrepreneurship

Sheet DATA PNLT KHUSUS AKRE 2025
A1: No | B1: No. SK | C1: No. Kontrak | D1: Judul Penelitian | E1: Nama Skema | F1: Tahun Usulan | G1: Tahun Pelaksanaan Kegiatan | H1: Lama Kegiatan (bulan) | I1: Bidang Fokus | J1: Dana Disetujui | K1: Nama Institusi Penerima Dana | L1: Target TKT | M1: Nama Program Hibah | N1: Kategori Sumber Dana | O1: Negara Sumber Dana | P1: Sumber Dana | Q1: Sinta ID Ketua | R1: Nama Ketua | S1: NIDN Ketua | T1: DANA KETUA | U1: Prodi Ketua | V1: Prodi Ketua (2) | W1: Prodi Ketua (3) | X1: Fakultas Ketua | Y1: Institusi Ketua | Z1: Sinta ID Institusi Ketua | AA1: Kode PT Ketua | AB1: Sinta ID Member1 | AC1: NIDN Member1 | AD1: Nama Anggota 1 | AE1: Dana Anggota 1 | AF1: Prodi Member 1 | AG1: Prodi Member 1 (2) | AH1: Prodi Anggota 1 (3) | AI1: Fakultas | AJ1: PT | AK1: Sinta ID Member2 | AL1: NIDN Member2 | AM1: Nama Anggota 2 | AN1: Dana Anggota 2 | AO1: Prodi Anggota 2 | AP1: Prodi Anggota 2 (2) | AQ1: Prodi Anggota 2 (3) | AR1: Fakultas3 | AS1: PT4 | AT1: Sinta ID Member3 | AU1: NIDN Member3 | AV1: Nama Anggota 3 | AW1: Dana Anggota 3 | AX1: Prodi Anggota 3 | AY1: Prodi Anggota 3 (2) | AZ1: Fakultas Anggota 3 | BA1: PT Anggota 3 | BB1: Sinta ID Member4 | BC1: NIDN Member4 | BD1: Nama Member4 | BE1: Dana Anggota 4 | BF1: Prodi Anggota 4 | BG1: Prodi Anggota 4 (2) | BH1: Fakultas Anggota 4 | BI1: PT Anggota 4 | BJ1: Sinta ID Member5 | BK1: NIDN Member5 | BL1: Nama Member5 | BM1: Prodi Anggota 5 | BN1: Fakultas Anggota 5 | BO1: Dana Anggota 5 | BP1: SDG | BQ1: Proposal | BR1: Laporan Akhir | BS1: Nama Mh | BT1: Prodi, Fak, PT Mhs1 | BU1: Nama Mhs2 | BV1: Prodi, Fak, PT Mhs2 | BW1: Nama Mhs3 | BX1: Prodi, Fak, PT Mhs3 | BY1: Nama Mhs4 | BZ1: Prodi Mhs4 | CA1: Nama Mhs5 | CB1: Prodi Mhs5 | CC1: Nama Mhs6 | CD1: Prodi Mhs6 | CE1: Nama Mhs7 | CF1: Prodi Mhs7 | CG1: Luaran Wajib | CH1: Capaian Luaran Wajib | CI1: Luaran Tambahan | CJ1: Capaian Luaran Tambahan
C2: 10/KP/LPPM-UWP/K-1/II/2018 | D2: RANCANGAN TEORI BAPAKISME TERHADAP PRODUKTIFITAS KADER POSYANDU SEBAGAI PENGGUNA SISTEM INFORMASI KMS | E2: Penelitian Hibah Eksternal | F2: 2018 | G2: 2018 | I2: Teknologi Informasi dan Komunikasi | J2: 16750000 | K2: Institut Teknologi Telkom Surabaya | O2: ID | P2: ITTelkom Surabaya | R2: Ully Asfari | T2: =J2 -> 16750000 | U2: Sistem Informasi | X2: FTII | AD2: Ir SUBADERI M.M | AE2: =J2 -> 16750000
C4: 214/PNLT3/PPM/III/2019 | D4: PENGEMBANGAN SISTEM KENDALI KUANTITAS AIR PADA TANAMAN HIDROPONIK BERBASIS INTERNET OF THINGS (IOT) | E4: Penelitian Dana Internal (PDI) | F4: 2019 | G4: 2019 | H4: 10 | J4: 8880000 | K4: Institut Teknologi Telkom Surabaya | L4: 4 | M4: Penelitian Kompetitif Internal | N4: Internal | O4: ID | P4: ITTelkom Surabaya | R4: Ubaidillah Umar | T4: =J4 -> 8880000 | U4: Teknik Komputer | X4: FTE | AD4: Helmy Widyantara | AE4: =J4 -> 8880000 | AF4: Teknologi Informasi | AG4: Sistem Informasi | AI4: FTII | BQ4: Proposal | BR4: Laporan Akhir | BS4: Rizal Fathurrahman | BU4: Alfrido Ramadhana KP
C5: 214/PNLT3/PPM/III/2019 | D5: Superposisi Gelombang Sinus Sebagai Media Pembelajaran Gelombang Dan Bunyi Pada Matakuliah Fisika Dasar Screen reader support enabled. | E5: Penelitian Dana Internal (PDI) | F5: 2019 | G5: 2019 | H5: 6 | J5: 4114000 | K5: Institut Teknologi Telkom Surabaya | L5: 3 | M5: Penelitian Kompetitif Internal | N5: Internal | O5: ID | P5: ITTelkom Surabaya | R5: Dwi Edi Setyawan | T5: =J5 -> 4114000 | U5: Teknik Komputer | X5: FTE | AD5: Billy Montolalu | AE5: =J5 -> 4114000 | AF5: Teknik Komputer | AI5: FTE | BQ5: Proposal | BR5: Laporan Akhir | BS5: Danang Taufik Kurnianto | BU5: Muhammad Syaiful Islam
C6: 214/PNLT3/PPM/III/2019 | D6: Rancang Bangun Modul Praktikum Harmonisasi Nada Sebagai Media Pembelajaran Gelombang Dan Bunyi Pada Matakuliah Fisika Dasar | E6: Penelitian Dana Internal (PDI) | F6: 2019 | G6: 2019 | H6: 6 | J6: 4752000 | K6: Institut Teknologi Telkom Surabaya | L6: 3 | M6: Penelitian Kompetitif Internal | N6: Internal | O6: ID | P6: ITTelkom Surabaya | R6: Dwi Edi Setyawan | T6: =J6 -> 4752000 | U6: Teknik Komputer | X6: FTE | AD6: Ardiansyah Al farouq | AE6: =J6 -> 4752000 | AF6: Teknik Komputer | AI6: FTE | BQ6: Proposal | BR6: Laporan Akhir | BS6: Muhammad Yanuar Muhaimin | BU6: Muhammad Huzaimi Maulana
C7: 214/PNLT3/PPM/III/2019 | D7: Analisis Kepuasan Pelanggan Terhadap Layanan Penyedia Jasa Transportasi Online Menggunakan Fuzzy Service Quality | E7: Penelitian Dana Internal (PDI) | F7: 2019 | G7: 2019 | H7: 8 | J7: 9627000 | K7: Institut Teknologi Telkom Surabaya | M7: Penelitian Kompetitif Internal | N7: Internal | O7: ID | P7: ITTelkom Surabaya | R7: Hawwin Mardhiana | T7: =J7 -> 9627000 | U7: Sistem Informasi | X7: FTII | AD7: Ully Asfari | AE7: =J7 -> 9627000 | AF7: Sistem Informasi | AI7: FTII | AM7: Anfazul Faridatul Azizah | AN7: =J7 -> 9627000 | AO7: Sistem Informasi | AR7: FTII | AV7: Rizqa Amelia Zunaidi | AW7: =J7 -> 9627000 | AX7: Teknik Industri | AZ7: FTII | BQ7: Proposal | BR7: Laporan Akhir | BS7: Tanang Satrio Adi
C8: 214/PNLT3/PPM/III/2019 | D8: Sistem Akuaponik Berbasis IOT pada Urban Farming | E8: Penelitian Dana Internal (PDI) | F8: 2019 | G8: 2019 | H8: 6 | J8: 11120000 | K8: Institut Teknologi Telkom Surabaya | L8: 6 | M8: Penelitian Kompetitif Internal | N8: Internal | O8: ID | P8: ITTelkom Surabaya | R8: Yupit Sudianto | T8: =J8 -> 11120000 | U8: Sistem Informasi | X8: FTII | AD8: Dimas Adiputra | AE8: =J8 -> 11120000 | AF8: Teknik Elektro | AI8: FTE | AM8: Fidi Wincoko Putro | AN8: =J8 -> 11120000 | AO8: Rekayasa Perangkat Lunak | AR8: FTII | AV8: Dominggo Bayu Baskara | AW8: =J8 -> 11120000 | AX8: Teknik Industri | AZ8: FTII | BD8: Noerma Pudji Istyanto | BE8: =J8 -> 11120000 | BF8: Sistem Informasi | BH8: FTII | BQ8: Proposal | BR8: Laporan Akhir | BS8: Tanfirul Roibafi Muhammad | BT8: SI, FTII, ITTS | BU8: Dhimas Bintang Bagaskara | BV8: RPL, FTII, ITTS
C9: 214/PNLT3/PPM/III/2019 | D9: Antena Dengan Beamforming Sederhana Untuk Komunikasi Robot Bergerak | E9: Penelitian Dana Internal (PDI) | F9: 2019 | G9: 2019 | H9: 9 | J9: 11400000 | K9: Institut Teknologi Telkom Surabaya | L9: 4 | M9: Penelitian Kompetitif Internal | N9: Internal | O9: ID | P9: ITTelkom Surabaya | R9: Muhsin | T9: =J9 -> 11400000 | U9: Teknik Telekomunikasi | V9: Teknik Elektro | X9: FTE | AD9: Walid Maulana Hadiansyah | AE9: =J9 -> 11400000 | AF9: Teknik Telekomunikasi | AI9: FTE | AM9: Tri Agus Djoko Kuntjoro | AN9: =J9 -> 11400000 | AO9: Teknik Telekomunikasi | AR9: FTE | BQ9: Proposal | BR9: Laporan Akhir | BS9: Aulia Putri Pramita | BU9: Riski Dwi Nur Cahyanti | BW9: Prasasti Desta Srihadi
C10: 214/PNLT3/PPM/III/2019 | D10: Identifikasi Posisi Kapal Mengunakan Internet Of Thing Sistem Untuk Mengurangi Antrian Kendaraan Truk Di Pelabuhan | E10: Penelitian Dana Internal (PDI) | F10: 2019 | G10: 2019 | H10: 10 | J10: 10125000 | K10: Institut Teknologi Telkom Surabaya | L10: Publikasi paper seminar | M10: Penelitian Kompetitif Internal | N10: Internal | O10: ID | P10: ITTelkom Surabaya | R10: Nilla Rachmaningrum | T10: =J10 -> 10125000 | U10: Teknik Telekomunikasi | X10: FTE | AD10: Hamzah Ulinuha Mustakim | AE10: =J10 -> 10125000 | AF10: Teknik Telekomunikasi | AI10: FTE | AM10: Tri Agus Djoko Kuntjoro | AN10: =J10 -> 10125000 | AO10: Teknik Telekomunikasi | AR10: FTE | BQ10: Proposal | BR10: Laporan Akhir | BS10: RM. Bagastyo Anggoro | BU10: Utami Ika Sulistya Rini
C11: 214/PNLT3/PPM/III/2019 | D11: Transporter Logistik Cerdas "SROBOT" | E11: Penelitian Dana Internal (PDI) | F11: 2019 | G11: 2019 | H11: 5 | J11: 11875000 | K11: Institut Teknologi Telkom Surabaya | L11: 4 | M11: Penelitian Kompetitif Internal | N11: Internal | O11: ID | P11: ITTelkom Surabaya | R11: Moch. Iskandar Riansyah | T11: =J11 -> 11875000 | U11: Teknik Elektro | X11: FTE | AD11: Lora Khaula Amifia | AE11: =J11 -> 11875000 | AF11: Teknik Elektro | AI11: FTE | BQ11: Proposal | BR11: Laporan Akhir | BS11: Putu Duta Hasta Putra | BU11: Getsemani Adi Bagus Maranata H
C12: 214/PNLT3/PPM/III/2019 | D12: Analisis Dan Deteksi Anomali Pada Perubahan Total Electron Content (Tec) Di Lapisan Ionosphare Sebelum Terjadi Gempa Bumi Menggunakan Ensemble Method. (Studi Kasus Gempa Bumi Palu Dan Lombok) | E12: Penelitian Dana Internal (PDI) | F12: 2019 | G12: 2019 | H12: 8 | J12: 3748000 | K12: Institut Teknologi Telkom Surabaya | L12: Jurnal Nasional Terakreditasi | M12: Penelitian Kompetitif Internal | N12: Internal | O12: ID | P12: ITTelkom Surabaya | R12: Bernadus Anggo Seno Aji | T12: =J12 -> 3748000 | U12: Teknologi Informasi | X12: FTII | AD12: Pangestu Widodo | AE12: =J12 -> 3748000 | AF12: Teknik Komputer | AI12: FTE | AM12: Arliyanti Nurdin | AN12: =J12 -> 3748000 | AO12: Teknologi Informasi | AR12: FTII | BQ12: Proposal | BR12: Laporan Akhir | BS12: Muhamad Rizal Dwi Adhipramana
C13: 214/PNLT3/PPM/III/2019 | D13: Simple Digital Wireless Transmitter & Receiver | E13: Penelitian Dana Internal (PDI) | F13: 2019 | G13: 2019 | H13: 10 | J13: 9400000 | K13: Institut Teknologi Telkom Surabaya | L13: HAKI | M13: Penelitian Kompetitif Internal | N13: Internal | O13: ID | P13: ITTelkom Surabaya | R13: Hamzah Ulinuha Mustakim | T13: =J13 -> 9400000 | U13: Teknik Telekomunikasi | X13: FTE | AD13: Nilla Rachmaningrum | AE13: =J13 -> 9400000 | AF13: Teknik Telekomunikasi | AI13: FTE | AM13: Walid Maulana Hadiansyah | AN13: =J13 -> 9400000 | AO13: Teknik Telekomunikasi | AR13: FTE | BQ13: Proposal | BR13: Laporan Akhir | BS13: Ahmad Maulana Rozaq
C14: 214/PNLT3/PPM/III/2019 | D14: Model Lokasi Spatial Dengan Fungsi Permintaan Yang Bergantung Pada Harga, Lokasi, Dan Diskon | E14: Penelitian Dana Internal (PDI) | F14: 2019 | G14: 2019 | H14: 8 | J14: 5296000 | K14: Institut Teknologi Telkom Surabaya | L14: 3 | M14: Penelitian Kompetitif Internal | N14: Internal | O14: ID | P14: ITTelkom Surabaya | R14: Abduh Sayid Albana | T14: =J14 -> 5296000 | U14: Teknik Industri | V14: Teknik Logistik | X14: FTII | AD14: Rahaditya Dimas Prihadianto | AE14: =J14 -> 5296000 | AF14: Teknik Industri | AI14: FTII | AM14: Sinta Dewi | AN14: =J14 -> 5296000 | BQ14: Proposal | BR14: Laporan Akhir | BS14: Muhammad Narendroduto Rokhyadi
C15: 214/PNLT3/PPM/III/2019 | D15: Pengawasan Dan Klasifikasi Kualitas Air Pdam Surabaya Berbasis Internet Of Things | E15: Penelitian Dana Internal (PDI) | F15: 2019 | G15: 2019 | H15: 6 | J15: 10250000 | K15: Institut Teknologi Telkom Surabaya | L15: 4 | M15: Penelitian Kompetitif Internal | N15: Internal | O15: ID | P15: ITTelkom Surabaya | R15: Dimas Adiputra | T15: =J15 -> 10250000 | U15: Teknik Elektro | X15: FTE | AD15: Anifatul Faricha | AE15: =J15 -> 10250000 | AF15: Teknik Elektro | AI15: FTE | AM15: Moch. Iskandar Riansyah | AN15: =J15 -> 10250000 | AO15: Teknik Elektro | AR15: FTE | AV15: Billy Montolalu | AW15: =J15 -> 10250000 | AX15: Teknik Komputer | AZ15: FTE | BQ15: Proposal | BR15: Laporan Akhir | BS15: Fauzan Abdul Rasyid | BU15: Moch. Bagus Indrastata
C16: 214/PNLT3/PPM/III/2019 | D16: Permodelan Permintaan Yang Mempertimbangkan Harga, Lokasi Dan Rebate | E16: Penelitian Dana Internal (PDI) | F16: 2019 | G16: 2019 | H16: 6 | J16: 6800000 | K16: Institut Teknologi Telkom Surabaya | L16: 2 | M16: Penelitian Kompetitif Internal | N16: Internal | O16: ID | P16: ITTelkom Surabaya | R16: Wahyu Andy Prastyabudi | T16: =J16 -> 6800000 | U16: Teknik Industri | X16: FTII | AD16: Sinta Dewi | AE16: =J16 -> 6800000 | AM16: Rizqa Amelia Zunaidi | AN16: =J16 -> 6800000 | AO16: Teknik Industri | AR16: FTII | BQ16: Proposal | BR16: Laporan Akhir | BS16: Nisrina Salsabila
C17: 214/PNLT3/PPM/III/2019 | D17: Koordinasi vd Kompetisi: Aplikasi Hotelling Model Pada Pelabuhan Peti Kemas Surabaya | E17: Penelitian Dana Internal (PDI) | F17: 2019 | G17: 2019 | H17: 10 | J17: 4800000 | K17: Institut Teknologi Telkom Surabaya | L17: 3 | M17: Penelitian Kompetitif Internal | N17: Internal | O17: ID | P17: ITTelkom Surabaya | R17: Rahaditya Dimas Prihadianto | T17: =J17 -> 4800000 | U17: Teknik Industri | X17: FTII | AD17: Abduh Sayid Albana | AE17: =J17 -> 4800000 | AF17: Teknik Industri | AG17: Teknik Logistik | AI17: FTII | AM17: Dominggo Bayu Baskara | AN17: =J17 -> 4800000 | AO17: Teknik Industri | AR17: FTII | BQ17: Proposal | BR17: Laporan Akhir | BS17: Shanggabuana Adhitya Shamaradewa
C18: 214/PNLT3/PPM/III/2019 | D18: Rancang Bangun Sistem Informasi Transportasi Umum Di Surabaya Mengguanakan Google Maps APIs Dan Firebase Pada Perangkat | E18: Penelitian Dana Internal (PDI) | F18: 2019 | G18: 2019 | H18: 10 | J18: 10748000 | K18: Institut Teknologi Telkom Surabaya | L18: Aplikasi Android, Jurnal Nasional Terakreditasi, Seminar Internasional Terindeks IEEE | M18: Penelitian Kompetitif Internal | N18: Internal | O18: ID | P18: ITTelkom Surabaya | R18: Farah Zakiyah Rahmanti | T18: =J18 -> 10748000 | U18: Teknologi Informasi | X18: FTII | AD18: Khodijah Amiroh | AE18: =J18 -> 10748000 | AF18: Teknologi Informasi | AI18: FTII | AM18: Oktavia Ayu Permata | AN18: =J18 -> 10748000 | AO18: Teknologi Informasi | AR18: FTII | AV18: Philip Tobianto Daely | AW18: =J18 -> 10748000 | AX18: Teknologi Informasi | AZ18: FTII | BQ18: Proposal | BR18: Laporan Akhir | BS18: Anas Ittaqullah
C19: 214/PNLT3/PPM/III/2019 | D19: Voice Command Dalam Rumah Pintar Berbasis Internet Of Things | E19: Penelitian Dana Internal (PDI) | F19: 2019 | G19: 2019 | H19: 3 | J19: 8681500 | K19: Institut Teknologi Telkom Surabaya | L19: Artikel Ilmiah dimuat di Jurnal | M19: Penelitian Kompetitif Internal | N19: Internal | O19: ID | P19: ITTelkom Surabaya | R19: Billy Montolalu | T19: =J19 -> 8681500 | U19: Teknik Komputer | X19: FTE | AD19: Ardiansyah Al farouq | AE19: =J19 -> 8681500 | AF19: Teknik Komputer | AI19: FTE | BQ19: Proposal | BR19: Laporan Akhir | BS19: Danu Diningrat | BU19: Alvin Tamado Cahaya
C20: 214/PNLT3/PPM/III/2019 | D20: Pengembangan Sistem Cerdas Untuk Prediksi Jatuh Berbasis Accelerometer Dan Gyroscope Dalam Rangka Pencegahan Cedera Fatal Pada Geriatri | E20: Penelitian Dana Internal (PDI) | F20: 2019 | G20: 2019 | H20: 10 | J20: 10025000 | K20: Institut Teknologi Telkom Surabaya | L20: 3 | M20: Penelitian Kompetitif Internal | N20: Internal | O20: ID | P20: ITTelkom Surabaya | R20: Dewi Rahmawati | T20: =J20 -> 10025000 | U20: Rekayasa Perangkat Lunak | X20: FTII | AD20: Ardian Yusuf Wicaksono | AE20: =J20 -> 10025000 | AF20: Informatika | AI20: FTII | AM20: Khodijah Amiroh | AN20: =J20 -> 10025000 | AO20: Teknologi Informasi | AR20: FTII | AV20: Titus Kristanto | AW20: =J20 -> 10025000 | AX20: Rekayasa Perangkat Lunak | AY20: Sistem Informasi | AZ20: FTII | BQ20: Proposal | BR20: Laporan Akhir
C21: 214/PNLT3/PPM/III/2019 | D21: Manajemen Energi Menggunakan Internet Of Things Untuk Smart Home | E21: Penelitian Dana Internal (PDI) | F21: 2019 | G21: 2019 | H21: 6 | J21: 6574000 | K21: Institut Teknologi Telkom Surabaya | L21: Paper Scopus | M21: Penelitian Kompetitif Internal | N21: Internal | O21: ID | P21: ITTelkom Surabaya | R21: Isa Hafidz | T21: =J21 -> 6574000 | U21: Teknik Elektro | X21: FTE | AD21: Moch. Iskandar Riansyah | AE21: =J21 -> 6574000 | AF21: Teknik Elektro | AI21: FTE | AM21: Dimas Adiputra | AN21: =J21 -> 6574000 | AO21: Teknik Elektro | AR21: FTE | BQ21: Proposal | BR21: Laporan Akhir | BS21: Fathur Alfariz | BU21: Nova H. M. Soetarno
A23: 1 | B23: REK.623/PNLT3/PPM/III/2020 | C23: 544/PNLT3/PPM/III/2020 | D23: PENGARUH TIPE MEDIA SOSIAL TERHADAP HUBUNGAN ANTARA INFORMASI PADA IKLAN PRODUK UKM INDUSTRI SANDANG DENGAN INTENSI MEMBELI PADA INFORMATION ACCEPTANCE MODEL (IACM) | E23: Penelitian Dana Internal (PDI) | F23: 2020 | G23: 2020 | H23: 10 | I23: Manajemen Industri | J23: 4563200 | K23: Institut Teknologi Telkom Surabaya | L23: 1 | N23: Internal | O23: ID | P23: ITTelkom Surabaya | Q23: 6681051 | R23: Rizqa Amelia Zunaidi | S23: 0711069301 | T23: =J23 -> 4563200 | U23: Teknik Industri | X23: FTEIC | AB23: 6680627 | AC23: 0703119301 | AD23: Benazir Imam Arif Muttaqin | AE23: =J23 -> 4563200 | AF23: Teknik Industri | AI23: FTEIC | AJ23: ITTelkom Surabaya | BQ23: Proposal | BR23: Laporan Akhir | CG23: Jurnal Nasional Terakreditasi | CI23: Seminar Internasional
A24: 2 | B24: REK.623/PNLT3/PPM/III/2020 | C24: 545/PNLT3/PPM/III/2020 | D24: Studi Kelayakan Teknologi Klasifikasi Otomatis Berbasis Convolutional Neural Network Pada Sistem Penerimaan Mahasiswa Baru | E24: Penelitian Dana Internal (PDI) | F24: 2020 | G24: 2020 | H24: 10 | I24: Studi Kelayakan | J24: 5820000 | K24: Institut Teknologi Telkom Surabaya | L24: 3 | N24: Internal | O24: ID | P24: ITTelkom Surabaya | Q24: 6682237 | R24: Dominggo Bayu Baskara | S24: 0722069004 | T24: =J24 -> 5820000 | U24: Bisnis Digital | X24: FTIB | AB24: 6680626 | AC24: 0727099201 | AD24: Ardian Yusuf Wicaksono | AE24: =J24 -> 5820000 | AF24: Informatika | AI24: FTIB | AJ24: ITTelkom Surabaya | AK24: 6680628 | AL24: 0730058702 | AM24: Fidi Wincoko Putro | AN24: =J24 -> 5820000 | AO24: Rekayasa Perangkat Lunak | AR24: FTIB | AS24: ITTelkom Surabaya | BQ24: Proposal | BR24: Laporan Akhir | CG24: Jurnal Nasional
A25: 3 | B25: REK.623/PNLT3/PPM/III/2020 | C25: 546/PNLT3/PPM/III/2020 | D25: 2D TO 3D MRI BRAIN SEGMENTATION MENGGUNAKAN U-NET AND MASK R-CNN METHOD UNTUK PENDUDUK DAERAH MARITIM | E25: Penelitian Dana Internal (PDI) | F25: 2020 | G25: 2020 | H25: 10 | I25: Machine Learning | J25: 13337500 | K25: Institut Teknologi Telkom Surabaya | L25: 3 | M25: Penelitian Kompetitif Internal | N25: Internal | O25: ID | P25: ITTelkom Surabaya | Q25: 6680622 | R25: Dewi Rahmawati | S25: 0709039401 | T25: =J25 -> 13337500 | U25: Rekayasa Perangkat Lunak | X25: FTIB | Y25: ITTelkom Surabaya | Z25: 8140 | AA25: 072019 | AB25: 6680626 | AC25: 0727099201 | AD25: Ardian Yusuf Wicaksono | AE25: =J25 -> 13337500 | AF25: Informatika | AI25: FTIB | AJ25: ITTelkom Surabaya | BQ25: Proposal | BR25: Laporan Akhir | CG25: Jurnal Nasional Terakreditasi | CI25: Seminar Internasional
A26: 4 | B26: REK.623/PNLT3/PPM/III/2020 | C26: 547/PNLT3/PPM/III/2020 | D26: Water Monitoring Using Internet of Things (IoT) Gen. 1 | E26: Penelitian Dana Internal (PDI) | F26: 2020 | G26: 2020 | H26: 10 | I26: Kemaritiman | J26: 15883750 | K26: Institut Teknologi Telkom Surabaya | L26: 4 | N26: Internal | O26: ID | P26: ITTelkom Surabaya | Q26: 6680651 | R26: Dimas Adiputra | S26: 0725059301 | T26: =J26 -> 15883750 | U26: Teknik Elektro | X26: FTEIC | AB26: 6680631 | AC26: 0704069202 | AD26: Anifatul Faricha | AE26: =J26 -> 15883750 | AF26: Teknik Elektro | AI26: FTEIC | AJ26: ITTelkom Surabaya | AK26: 6680685 | AL26: 0721068802 | AM26: Moch. Iskandar Riansyah | AN26: =J26 -> 15883750 | AO26: Teknik Elektro | AR26: FTEIC | AS26: ITTelkom Surabaya | BQ26: Proposal | BR26: Laporan Akhir | CG26: Jurnal | CI26: Proseding internasional, Prototype
A27: 5 | B27: REK.623/PNLT3/PPM/III/2020 | C27: 548/PNLT3/PPM/III/2020 | D27: Simulasi Model Hoteliing Pada Pelabuhan Peti Kemas Surabaya | E27: Penelitian Dana Internal (PDI) | F27: 2020 | G27: 2020 | H27: 10 | I27: Simulasi Industri | J27: 5796000 | K27: Institut Teknologi Telkom Surabaya | L27: 3 | N27: Internal | O27: ID | P27: ITTelkom Surabaya | Q27: 6680618 | R27: Rahaditya Dimas Prihadianto | S27: 0725059202 | T27: =J27 -> 5796000 | U27: Teknik Industri | X27: FTEIC | AB27: 6680643 | AC27: 0702039003 | AD27: Abduh Sayid Albana | AE27: =J27 -> 5796000 | AF27: Teknik Logistik | AG27: Teknik Industri | AI27: FTEIC | AJ27: ITTelkom Surabaya | AK27: 6682237 | AL27: 722069004 | AM27: Dominggo Bayu | AN27: =J27 -> 5796000 | AO27: Bisnis Digital | AR27: FTIB | AS27: ITTelkom Surabaya | BQ27: Proposal | BR27: Laporan Akhir | CG27: Jurnal Nasional Terakreditasi | CI27: Seminar Internasional
A28: 6 | B28: REK.623/PNLT3/PPM/III/2020 | C28: 549/PNLT3/PPM/III/2020 | D28: Desain Sistem Monitoring Solar Farm dengan Menggunakan PV Inverter pada Bangunan | E28: Penelitian Dana Internal (PDI) | F28: 2020 | G28: 2020 | H28: 10 | I28: Teknologi Informasi dan Komunikasi | J28: 15035000 | K28: Institut Teknologi Telkom Surabaya | L28: 2 | N28: Internal | O28: ID | P28: ITTelkom Surabaya | Q28: 6680612 | R28: Isa Hafidz | S28: 0728059203 | T28: =J28 -> 15035000 | U28: Teknik Elektro | X28: FTEIC | AB28: 6680683 | AC28: 0729088704 | AD28: Billy Montolalu | AE28: =J28 -> 15035000 | AF28: Rekayasa Perangkat Lunak | AI28: FTIB | AJ28: ITTelkom Surabaya | AK28: 6680741 | AL28: 727059002 | AM28: Hamzah Ulinuha Mustakim | AN28: =J28 -> 15035000 | AO28: Teknik Telekomunikasi | AR28: FTEIC | AS28: ITTelkom Surabaya | BQ28: Proposal | BR28: Laporan Akhir | CG28: Jurnal | CI28: Modul Pelatihan, Modul Praktikum
A29: 7 | B29: REK.623/PNLT3/PPM/III/2020 | C29: 550/PNLT3/PPM/III/2020 | D29: EVAN (Emergency Vehiche Automatic Notification) | E29: Penelitian Dana Internal (PDI) | F29: 2020 | G29: 2020 | H29: 10 | I29: Transportasi | J29: 12530400 | K29: Institut Teknologi Telkom Surabaya | L29: 2 | N29: Internal | O29: ID | P29: ITTelkom Surabaya | Q29: 6682174 | R29: Khodijah Amiroh | S29: 0708069202 | T29: =J29 -> 12530400 | U29: Teknologi Informasi | X29: FTIB | AB29: 6680664 | AC29: 0715128708 | AD29: Farah Zakiyah Rahmanti | AE29: =J29 -> 12530400 | AF29: Teknologi Informasi | AI29: FTIB | AJ29: ITTelkom Surabaya | AK29: 6680680 | AL29: 704039202 | AM29: Bernadus Anggo Seno Aji | AN29: =J29 -> 12530400 | AO29: Teknologi Informasi | AR29: FTIB | AS29: ITTelkom Surabaya | BQ29: Proposal | BR29: Laporan Akhir | CG29: Jurnal Nasional Terakreditasi | CI29: HKI
A30: 8 | B30: REK.623/PNLT3/PPM/III/2020 | C30: 551/PNLT3/PPM/III/2020 | D30: Analisis Karakteristik Peniaian Kinerja Manajerial Terhadap Pengaruh Motivasi Dan Kreativitas Menggunakan Metode Graphic Rating Scale Pada Instansi XYZ | E30: Penelitian Dana Internal (PDI) | F30: 2020 | G30: 2020 | H30: 10 | I30: Teknologi Informasi dan Komunikasi | J30: 6661475 | K30: Institut Teknologi Telkom Surabaya | L30: 3 | N30: Internal | O30: ID | P30: ITTelkom Surabaya | Q30: 259781 | R30: Titus Kristanto | S30: 0710028604 | T30: =J30 -> 6661475 | U30: Bisnis Digital | V30: Sistem Informasi | X30: FTIB | AB30: 6680698 | AC30: 0709128101 | AD30: Mohammad Sholik | AE30: =J30 -> 6661475 | AF30: Rekayasa Perangkat Lunak | AI30: FTIB | AJ30: ITTelkom Surabaya | AK30: 6744406 | AL30: 0709059004 | AM30: Muhamad Nasrullah | AN30: =J30 -> 6661475 | AO30: Sistem Informasi | AR30: FTIB | AS30: ITTelkom Surabaya | BQ30: Proposal | BR30: Laporan Akhir | CG30: Jurnal Nasional Terakreditasi | CI30: Seminar Internasional, Hak Cipta
A31: 9 | B31: REK.623/PNLT3/PPM/III/2020 | C31: 552/PNLT3/PPM/III/2020 | D31: Perancangan Data Warehouse untuk Menunjang Akreditasi Program Studi | E31: Penelitian Dana Internal (PDI) | F31: 2020 | G31: 2020 | H31: 6 | I31: Warehouse Management System | J31: 4600000 | K31: Institut Teknologi Telkom Surabaya | L31: 3 | N31: Internal | O31: ID | P31: ITTelkom Surabaya | Q31: 6764236 | R31: Rokhmatul Insani | S31: 0704068902 | T31: =J31 -> 4600000 | U31: Sistem Informasi | X31: FTIB | AB31: 6665306 | AC31: 0703129001 | AD31: Ully Asfari | AE31: =J31 -> 4600000 | AF31: Sistem Informasi | AI31: FTIB | AJ31: ITTelkom Surabaya | BQ31: Proposal | BR31: Laporan Akhir | CG31: Jurnal Sinta 2 | CI31: Seminar Internasional
A32: 10 | B32: REK.623/PNLT3/PPM/III/2020 | C32: 553/PNLT3/PPM/III/2020 | D32: Penelusuran Sumber Gas Pada Kondisi Turbulensi Mekanis Menggunakan Mobile Robot | E32: Penelitian Dana Internal (PDI) | F32: 2020 | G32: 2020 | H32: 7 | I32: Transportasi | J32: 11932940 | K32: Institut Teknologi Telkom Surabaya | L32: 4 | N32: Internal | O32: ID | P32: ITTelkom Surabaya | Q32: 6680633 | R32: Helmy Widyantara | S32: 0717017902 | T32: =J32 -> 11932940 | U32: Teknologi Informasi | V32: Sistem Informasi | X32: FTIB | AB32: 6680629 | AC32: 0727048809 | AD32: Ubaidillah Umar | AE32: =J32 -> 11932940 | AF32: Teknik Komputer | AI32: FTEIC | AJ32: ITTelkom Surabaya | BQ32: Proposal | BR32: Laporan Akhir | CG32: Jurnal Internasional
A33: 11 | B33: REK.623/PNLT3/PPM/III/2020 | C33: 554/PNLT3/PPM/III/2020 | D33: Antenna MIMO 5G-NR Band N77 dengan Korelasi Rendah untuk Base Station Komunikasi Robot Bergerak | E33: Penelitian Dana Internal (PDI) | F33: 2020 | G33: 2020 | H33: 10 | I33: Teknologi Informasi dan Komunikasi | J33: 11270000 | K33: Institut Teknologi Telkom Surabaya | L33: 4 | N33: Internal | O33: ID | P33: ITTelkom Surabaya | Q33: 6680615 | R33: Muhsin | S33: 0703049401 | T33: =J33 -> 11270000 | U33: Teknik Telekomunikasi | V33: Teknik Elektro | X33: FTEIC | AB33: 6680645 | AC33: 0713108902 | AD33: Walid Maulana Hadiansyah | AE33: =J33 -> 11270000 | AF33: Teknik Telekomunikasi | AI33: FTEIC | AJ33: ITTelkom Surabaya | BQ33: Proposal | BR33: Laporan Akhir | CG33: Jurnal Internasional
